Workbook

Sheet Attendance_Data
A1: Date | B1: Day | C1: Lecture_No | D1: Start_Time | E1: End_Time | F1: Subject | G1: Faculty_ID | H1: Semester | I1: Branch | J1: Section | K1: Classroom | L1: Total_Students | M1: Present | N1: Attendance_Percentage | O1: Previous_Lecture_Attendance | P1: Gap_Since_Previous_Lecture | Q1: Practical_Theory | R1: Test_Week | S1: Assignment_Due | T1: Holiday_Near | U1: Weather | V1: Special_Event | W1: Faculty_Experience | X1: Week_Number | Y1: Day_of_Semester | Z1: Time_of_Day
A2: 46188 | B2: Monday | C2: 1 | D2: 0.38541667 | E2: 0.42708333 | F2: Soft Skill | G2: SDa | H2: III | I2: MCA | J2: A | K2: Seminar Hall | L2: 103 | M2: =RANDBETWEEN(40,103) -> 40 | N2: =IF(OR(L2="", M2=""), "", (M2/L2)*100) -> 38.834951 | O2: 72.228754 | P2: =IF(C2=1, 0, IF(AND(A2=A1, J2=J1), ROUND(MAX(0, (D2-E1)*24), 2), 0)) -> 0 | Q2: Theory | R2: No | S2: =IF(OR(ISNUMBER(SEARCH("Guest", F2)), ISNUMBER(SEARCH("Hands-on", F2)), ISNUMBER(SEARCH("Project", F2)), B2="Friday"), "Yes", "No") -> No | T2: Yes | U2: =IF(MONTH(A2)=6, IF(DAY(A2)<20, "Sunny", "Cloudy"), IF(OR(MONTH(A2)=7, MONTH(A2)=8), "Rainy", "Sunny")) -> Sunny | V2: No | W2: {=_xlfn.IFS( OR(F2="Selenium (Hands-on)",F2="Guest Lecture: HR Interview"),6, OR(F2="Soft Skill",F2="Soft Skill (Examination)",F2="AWS Training",F2="AWS Session"),7, OR(ISNUMBER(SEARCH("MAD",F2)),ISNUMBER(SEARCH("STQA",F2)),F2="CI/CD Session"),8, OR(ISNUMBER(SEARCH("Cloud",F2)),F2="Industry Readiness Program",ISNUMBER(SEARCH("Talenlio",F2))),9, OR(ISNUMBER(SEARCH("Innovation",F2)),F2="Mini Project"),10, OR(ISNUMBER(SEARCH("Data Science",F2)),ISNUMBER(SEARCH("DS",F2))),11, ISNUMBER(SEARCH("Generative AI",F2)),12 =_xlfn.IFS( OR(F2="Selenium (Hands-on)",F2="Guest Lecture: HR Interview"),6, OR(F2="Soft Skill",F2="Soft Skill (Examination)",F2="AWS Training",F2="AWS Session"),7, OR(ISNUMBER(SEARCH("MAD",F2)),ISNUMBER(SEARCH("STQA",F2)),F2="CI/CD Session"),8, OR(ISNUMBER(SEARCH("Cloud",F2)),F2="Industry Readiness Program",ISNUMBER(SEARCH("Talenlio",F2))),9, OR(ISNUMBER(SEARCH("Innovation",F2)),F2="Mini Project"),10, OR(ISNUMBER(SEARCH("Data Science",F2)),ISNUMBER(SEARCH("DS",F2))),11, ISNUMBER(SEARCH("Generative AI",F2)),12 =_xlfn.IFS( OR(F2="Selenium (Hands-on)",F2="Guest Lecture: HR Interview"),6, OR(F2="Soft Skill",F2="Soft Skill (Examination)",F2="AWS Training",F2="AWS Session"),7, OR(ISNUMBER(SEARCH("MAD",F2)),ISNUMBER(SEARCH("STQA",F2)),F2="CI/CD Session"),8, OR(ISNUMBER(SEARCH("Cloud",F2)),F2="Industry Readiness Program",ISNUMBER(SEARCH("Talenlio",F2))),9, OR(ISNUMBER(SEARCH("Innovation",F2)),F2="Mini Project"),10, OR(ISNUMBER(SEARCH("Data Science",F2)),ISNUMBER(SEARCH("DS",F2))),11, ISNUMBER(SEARCH("Generative AI",F2)),12 =_xlfn.IFS( OR(F2="Selenium (Hands-on)",F2="Guest Lecture: HR Interview"),6, OR(F2="Soft Skill",F2="Soft Skill (Examination)",F2="AWS Training",F2="AWS Session"),7, OR(ISNUMBER(SEARCH("MAD",F2)),ISNUMBER(SEARCH("STQA",F2)),F2="CI/CD Session"),8, OR(ISNUMBER(SEARCH("Cloud",F2)),F2="Industry Readiness Program",ISNUMBER(SEARCH("Talenlio",F2))),9, OR(ISNUMBER(SEARCH("Innovation",F2)),F2="Mini Project"),10, OR(ISNUMBER(SEARCH("Data Science",F2)),ISNUMBER(SEARCH("DS",F2))),11, ISNUMBER(SEARCH("Generative AI",F2)),12 ))))} -> 7 | X2: 1 | Y2: 1 | Z2: Morning
A3: 46188 | B3: Monday | C3: 2 | D3: 0.42708333 | E3: 0.46875 | F3: Soft Skill | G3: SDa | H3: III | I3: MCA | J3: A | K3: Seminar Hall | L3: 103 | M3: =RANDBETWEEN(40,103) -> 72 | N3: =IF(OR(L3="",M3=""),"",M3/L3*100) -> 69.902913 | O3: {=IFERROR(LOOKUP(2, 1/((F$1:F2=F3)*(J$1:J2=J3)*(ROW(F$1:F2)<ROW(F3))), N$1:N2), "")} -> 38.834951 | P3: =IF(C3=1, 0, IF(AND(A3=A2, J3=J2), ROUND(MAX(0, (D3-E2)*24), 2), 0)) -> 0 | Q3: Theory | R3: No | S3: =IF(OR(ISNUMBER(SEARCH("Guest", F3)), ISNUMBER(SEARCH("Hands-on", F3)), ISNUMBER(SEARCH("Project", F3)), B3="Friday"), "Yes", "No") -> No | T3: Yes | U3: =IF(MONTH(A3)=6, IF(DAY(A3)<20, "Sunny", "Cloudy"), IF(OR(MONTH(A3)=7, MONTH(A3)=8), "Rainy", "Sunny")) -> Sunny | V3: No | W3: {=_xlfn.IFS( OR(F3="Selenium (Hands-on)",F3="Guest Lecture: HR Interview"),6, OR(F3="Soft Skill",F3="Soft Skill (Examination)",F3="AWS Training",F3="AWS Session"),7, OR(ISNUMBER(SEARCH("MAD",F3)),ISNUMBER(SEARCH("STQA",F3)),F3="CI/CD Session"),8, OR(ISNUMBER(SEARCH("Cloud",F3)),F3="Industry Readiness Program",ISNUMBER(SEARCH("Talenlio",F3))),9, OR(ISNUMBER(SEARCH("Innovation",F3)),F3="Mini Project"),10, OR(ISNUMBER(SEARCH("Data Science",F3)),ISNUMBER(SEARCH("DS",F3))),11, ISNUMBER(SEARCH("Generative AI",F3)),12 =_xlfn.IFS( OR(F3="Selenium (Hands-on)",F3="Guest Lecture: HR Interview"),6, OR(F3="Soft Skill",F3="Soft Skill (Examination)",F3="AWS Training",F3="AWS Session"),7, OR(ISNUMBER(SEARCH("MAD",F3)),ISNUMBER(SEARCH("STQA",F3)),F3="CI/CD Session"),8, OR(ISNUMBER(SEARCH("Cloud",F3)),F3="Industry Readiness Program",ISNUMBER(SEARCH("Talenlio",F3))),9, OR(ISNUMBER(SEARCH("Innovation",F3)),F3="Mini Project"),10, OR(ISNUMBER(SEARCH("Data Science",F3)),ISNUMBER(SEARCH("DS",F3))),11, ISNUMBER(SEARCH("Generative AI",F3)),12 =_xlfn.IFS( OR(F3="Selenium (Hands-on)",F3="Guest Lecture: HR Interview"),6, OR(F3="Soft Skill",F3="Soft Skill (Examination)",F3="AWS Training",F3="AWS Session"),7, OR(ISNUMBER(SEARCH("MAD",F3)),ISNUMBER(SEARCH("STQA",F3)),F3="CI/CD Session"),8, OR(ISNUMBER(SEARCH("Cloud",F3)),F3="Industry Readiness Program",ISNUMBER(SEARCH("Talenlio",F3))),9, OR(ISNUMBER(SEARCH("Innovation",F3)),F3="Mini Project"),10, OR(ISNUMBER(SEARCH("Data Science",F3)),ISNUMBER(SEARCH("DS",F3))),11, ISNUMBER(SEARCH("Generative AI",F3)),12 =_xlfn.IFS( OR(F3="Selenium (Hands-on)",F3="Guest Lecture: HR Interview"),6, OR(F3="Soft Skill",F3="Soft Skill (Examination)",F3="AWS Training",F3="AWS Session"),7, OR(ISNUMBER(SEARCH("MAD",F3)),ISNUMBER(SEARCH("STQA",F3)),F3="CI/CD Session"),8, OR(ISNUMBER(SEARCH("Cloud",F3)),F3="Industry Readiness Program",ISNUMBER(SEARCH("Talenlio",F3))),9, OR(ISNUMBER(SEARCH("Innovation",F3)),F3="Mini Project"),10, OR(ISNUMBER(SEARCH("Data Science",F3)),ISNUMBER(SEARCH("DS",F3))),11, ISNUMBER(SEARCH("Generative AI",F3)),12 ))))} -> 7 | X3: 1 | Y3: 1 | Z3: Morning
A4: 46188 | B4: Monday | C4: 3 | D4: 0.5625 | E4: 0.60416667 | F4: Guest Session: Generative AI Development - Opportunities for the Future | G4: AG | H4: III | I4: MCA | J4: A | K4: Seminar Hall | L4: 103 | M4: =RANDBETWEEN(40,103) -> 45 | N4: =IF(OR(L4="",M4=""),"",M4/L4*100) -> 43.68932 | O4: 60.749923 | P4: =IF(C4=1, 0, IF(AND(A4=A3, J4=J3), ROUND(MAX(0, (D4-E3)*24), 2), 0)) -> 2.25 | Q4: Theory | R4: No | S4: =IF(OR(ISNUMBER(SEARCH("Guest", F4)), ISNUMBER(SEARCH("Hands-on", F4)), ISNUMBER(SEARCH("Project", F4)), B4="Friday"), "Yes", "No") -> Yes | T4: Yes | U4: =IF(MONTH(A4)=6, IF(DAY(A4)<20, "Sunny", "Cloudy"), IF(OR(MONTH(A4)=7, MONTH(A4)=8), "Rainy", "Sunny")) -> Sunny | V4: Yes | W4: {=_xlfn.IFS( OR(F4="Selenium (Hands-on)",F4="Guest Lecture: HR Interview"),6, OR(F4="Soft Skill",F4="Soft Skill (Examination)",F4="AWS Training",F4="AWS Session"),7, OR(ISNUMBER(SEARCH("MAD",F4)),ISNUMBER(SEARCH("STQA",F4)),F4="CI/CD Session"),8, OR(ISNUMBER(SEARCH("Cloud",F4)),F4="Industry Readiness Program",ISNUMBER(SEARCH("Talenlio",F4))),9, OR(ISNUMBER(SEARCH("Innovation",F4)),F4="Mini Project"),10, OR(ISNUMBER(SEARCH("Data Science",F4)),ISNUMBER(SEARCH("DS",F4))),11, ISNUMBER(SEARCH("Generative AI",F4)),12 =_xlfn.IFS( OR(F4="Selenium (Hands-on)",F4="Guest Lecture: HR Interview"),6, OR(F4="Soft Skill",F4="Soft Skill (Examination)",F4="AWS Training",F4="AWS Session"),7, OR(ISNUMBER(SEARCH("MAD",F4)),ISNUMBER(SEARCH("STQA",F4)),F4="CI/CD Session"),8, OR(ISNUMBER(SEARCH("Cloud",F4)),F4="Industry Readiness Program",ISNUMBER(SEARCH("Talenlio",F4))),9, OR(ISNUMBER(SEARCH("Innovation",F4)),F4="Mini Project"),10, OR(ISNUMBER(SEARCH("Data Science",F4)),ISNUMBER(SEARCH("DS",F4))),11, ISNUMBER(SEARCH("Generative AI",F4)),12 =_xlfn.IFS( OR(F4="Selenium (Hands-on)",F4="Guest Lecture: HR Interview"),6, OR(F4="Soft Skill",F4="Soft Skill (Examination)",F4="AWS Training",F4="AWS Session"),7, OR(ISNUMBER(SEARCH("MAD",F4)),ISNUMBER(SEARCH("STQA",F4)),F4="CI/CD Session"),8, OR(ISNUMBER(SEARCH("Cloud",F4)),F4="Industry Readiness Program",ISNUMBER(SEARCH("Talenlio",F4))),9, OR(ISNUMBER(SEARCH("Innovation",F4)),F4="Mini Project"),10, OR(ISNUMBER(SEARCH("Data Science",F4)),ISNUMBER(SEARCH("DS",F4))),11, ISNUMBER(SEARCH("Generative AI",F4)),12 =_xlfn.IFS( OR(F4="Selenium (Hands-on)",F4="Guest Lecture: HR Interview"),6, OR(F4="Soft Skill",F4="Soft Skill (Examination)",F4="AWS Training",F4="AWS Session"),7, OR(ISNUMBER(SEARCH("MAD",F4)),ISNUMBER(SEARCH("STQA",F4)),F4="CI/CD Session"),8, OR(ISNUMBER(SEARCH("Cloud",F4)),F4="Industry Readiness Program",ISNUMBER(SEARCH("Talenlio",F4))),9, OR(ISNUMBER(SEARCH("Innovation",F4)),F4="Mini Project"),10, OR(ISNUMBER(SEARCH("Data Science",F4)),ISNUMBER(SEARCH("DS",F4))),11, ISNUMBER(SEARCH("Generative AI",F4)),12 ))))} -> FALSE | X4: 1 | Y4: 1 | Z4: Afternoon
A5: 46188 | B5: Monday | C5: 4 | D5: 0.60416667 | E5: 0.64583333 | F5: Guest Session: Generative AI Development - Opportunities for the Future | G5: AG | H5: III | I5: MCA | J5: A | K5: Seminar Hall | L5: 103 | M5: =RANDBETWEEN(40,103) -> 66 | N5: =IF(OR(L5="",M5=""),"",M5/L5*100) -> 64.07767 | O5: {=IFERROR(LOOKUP(2, 1/((F$1:F4=F5)*(J$1:J4=J5)*(ROW(F$1:F4)<ROW(F5))), N$1:N4), "")} -> 43.68932 | P5: =IF(C5=1, 0, IF(AND(A5=A4, J5=J4), ROUND(MAX(0, (D5-E4)*24), 2), 0)) -> 0 | Q5: Theory | R5: No | S5: =IF(OR(ISNUMBER(SEARCH("Guest", F5)), ISNUMBER(SEARCH("Hands-on", F5)), ISNUMBER(SEARCH("Project", F5)), B5="Friday"), "Yes", "No") -> Yes | T5: Yes | U5: =IF(MONTH(A5)=6, IF(DAY(A5)<20, "Sunny", "Cloudy"), IF(OR(MONTH(A5)=7, MONTH(A5)=8), "Rainy", "Sunny")) -> Sunny | V5: Yes | W5: {=_xlfn.IFS( OR(F5="Selenium (Hands-on)",F5="Guest Lecture: HR Interview"),6, OR(F5="Soft Skill",F5="Soft Skill (Examination)",F5="AWS Training",F5="AWS Session"),7, OR(ISNUMBER(SEARCH("MAD",F5)),ISNUMBER(SEARCH("STQA",F5)),F5="CI/CD Session"),8, OR(ISNUMBER(SEARCH("Cloud",F5)),F5="Industry Readiness Program",ISNUMBER(SEARCH("Talenlio",F5))),9, OR(ISNUMBER(SEARCH("Innovation",F5)),F5="Mini Project"),10, OR(ISNUMBER(SEARCH("Data Science",F5)),ISNUMBER(SEARCH("DS",F5))),11, ISNUMBER(SEARCH("Generative AI",F5)),12 =_xlfn.IFS( OR(F5="Selenium (Hands-on)",F5="Guest Lecture: HR Interview"),6, OR(F5="Soft Skill",F5="Soft Skill (Examination)",F5="AWS Training",F5="AWS Session"),7, OR(ISNUMBER(SEARCH("MAD",F5)),ISNUMBER(SEARCH("STQA",F5)),F5="CI/CD Session"),8, OR(ISNUMBER(SEARCH("Cloud",F5)),F5="Industry Readiness Program",ISNUMBER(SEARCH("Talenlio",F5))),9, OR(ISNUMBER(SEARCH("Innovation",F5)),F5="Mini Project"),10, OR(ISNUMBER(SEARCH("Data Science",F5)),ISNUMBER(SEARCH("DS",F5))),11, ISNUMBER(SEARCH("Generative AI",F5)),12 =_xlfn.IFS( OR(F5="Selenium (Hands-on)",F5="Guest Lecture: HR Interview"),6, OR(F5="Soft Skill",F5="Soft Skill (Examination)",F5="AWS Training",F5="AWS Session"),7, OR(ISNUMBER(SEARCH("MAD",F5)),ISNUMBER(SEARCH("STQA",F5)),F5="CI/CD Session"),8, OR(ISNUMBER(SEARCH("Cloud",F5)),F5="Industry Readiness Program",ISNUMBER(SEARCH("Talenlio",F5))),9, OR(ISNUMBER(SEARCH("Innovation",F5)),F5="Mini Project"),10, OR(ISNUMBER(SEARCH("Data Science",F5)),ISNUMBER(SEARCH("DS",F5))),11, ISNUMBER(SEARCH("Generative AI",F5)),12 =_xlfn.IFS( OR(F5="Selenium (Hands-on)",F5="Guest Lecture: HR Interview"),6, OR(F5="Soft Skill",F5="Soft Skill (Examination)",F5="AWS Training",F5="AWS Session"),7, OR(ISNUMBER(SEARCH("MAD",F5)),ISNUMBER(SEARCH("STQA",F5)),F5="CI/CD Session"),8, OR(ISNUMBER(SEARCH("Cloud",F5)),F5="Industry Readiness Program",ISNUMBER(SEARCH("Talenlio",F5))),9, OR(ISNUMBER(SEARCH("Innovation",F5)),F5="Mini Project"),10, OR(ISNUMBER(SEARCH("Data Science",F5)),ISNUMBER(SEARCH("DS",F5))),11, ISNUMBER(SEARCH("Generative AI",F5)),12 ))))} -> FALSE | X5: 1 | Y5: 1 | Z5: Afternoon
A6: 46189 | B6: Tuesday | C6: 1 | D6: 0.38541667 | E6: 0.42708333 | F6: Soft Skill | G6: SD | H6: III | I6: MCA | J6: A | K6: Seminar Hall | L6: 103 | M6: =RANDBETWEEN(40,103) -> 47 | N6: =IF(OR(L6="",M6=""),"",M6/L6*100) -> 45.631068 | O6: {=IFERROR(LOOKUP(2, 1/((F$1:F5=F6)*(J$1:J5=J6)*(ROW(F$1:F5)<ROW(F6))), N$1:N5), "")} -> 69.902913 | P6: =IF(C6=1, 0, IF(AND(A6=A5, J6=J5), ROUND(MAX(0, (D6-E5)*24), 2), 0)) -> 0 | Q6: Theory | R6: No | S6: =IF(OR(ISNUMBER(SEARCH("Guest", F6)), ISNUMBER(SEARCH("Hands-on", F6)), ISNUMBER(SEARCH("Project", F6)), B6="Friday"), "Yes", "No") -> No | T6: No | U6: =IF(MONTH(A6)=6, IF(DAY(A6)<20, "Sunny", "Cloudy"), IF(OR(MONTH(A6)=7, MONTH(A6)=8), "Rainy", "Sunny")) -> Sunny | V6: No | W6: {=_xlfn.IFS( OR(F6="Selenium (Hands-on)",F6="Guest Lecture: HR Interview"),6, OR(F6="Soft Skill",F6="Soft Skill (Examination)",F6="AWS Training",F6="AWS Session"),7, OR(ISNUMBER(SEARCH("MAD",F6)),ISNUMBER(SEARCH("STQA",F6)),F6="CI/CD Session"),8, OR(ISNUMBER(SEARCH("Cloud",F6)),F6="Industry Readiness Program",ISNUMBER(SEARCH("Talenlio",F6))),9, OR(ISNUMBER(SEARCH("Innovation",F6)),F6="Mini Project"),10, OR(ISNUMBER(SEARCH("Data Science",F6)),ISNUMBER(SEARCH("DS",F6))),11, ISNUMBER(SEARCH("Generative AI",F6)),12 =_xlfn.IFS( OR(F6="Selenium (Hands-on)",F6="Guest Lecture: HR Interview"),6, OR(F6="Soft Skill",F6="Soft Skill (Examination)",F6="AWS Training",F6="AWS Session"),7, OR(ISNUMBER(SEARCH("MAD",F6)),ISNUMBER(SEARCH("STQA",F6)),F6="CI/CD Session"),8, OR(ISNUMBER(SEARCH("Cloud",F6)),F6="Industry Readiness Program",ISNUMBER(SEARCH("Talenlio",F6))),9, OR(ISNUMBER(SEARCH("Innovation",F6)),F6="Mini Project"),10, OR(ISNUMBER(SEARCH("Data Science",F6)),ISNUMBER(SEARCH("DS",F6))),11, ISNUMBER(SEARCH("Generative AI",F6)),12 =_xlfn.IFS( OR(F6="Selenium (Hands-on)",F6="Guest Lecture: HR Interview"),6, OR(F6="Soft Skill",F6="Soft Skill (Examination)",F6="AWS Training",F6="AWS Session"),7, OR(ISNUMBER(SEARCH("MAD",F6)),ISNUMBER(SEARCH("STQA",F6)),F6="CI/CD Session"),8, OR(ISNUMBER(SEARCH("Cloud",F6)),F6="Industry Readiness Program",ISNUMBER(SEARCH("Talenlio",F6))),9, OR(ISNUMBER(SEARCH("Innovation",F6)),F6="Mini Project"),10, OR(ISNUMBER(SEARCH("Data Science",F6)),ISNUMBER(SEARCH("DS",F6))),11, ISNUMBER(SEARCH("Generative AI",F6)),12 =_xlfn.IFS( OR(F6="Selenium (Hands-on)",F6="Guest Lecture: HR Interview"),6, OR(F6="Soft Skill",F6="Soft Skill (Examination)",F6="AWS Training",F6="AWS Session"),7, OR(ISNUMBER(SEARCH("MAD",F6)),ISNUMBER(SEARCH("STQA",F6)),F6="CI/CD Session"),8, OR(ISNUMBER(SEARCH("Cloud",F6)),F6="Industry Readiness Program",ISNUMBER(SEARCH("Talenlio",F6))),9, OR(ISNUMBER(SEARCH("Innovation",F6)),F6="Mini Project"),10, OR(ISNUMBER(SEARCH("Data Science",F6)),ISNUMBER(SEARCH("DS",F6))),11, ISNUMBER(SEARCH("Generative AI",F6)),12 ))))} -> 7 | X6: 1 | Y6: 2 | Z6: Morning
A7: 46189 | B7: Tuesday | C7: 2 | D7: 0.42708333 | E7: 0.46875 | F7: Soft Skill | G7: SD | H7: III | I7: MCA | J7: A | K7: Seminar Hall | L7: 103 | M7: =RANDBETWEEN(40,103) -> 67 | N7: =IF(OR(L7="",M7=""),"",M7/L7*100) -> 65.048544 | O7: {=IFERROR(LOOKUP(2, 1/((F$1:F6=F7)*(J$1:J6=J7)*(ROW(F$1:F6)<ROW(F7))), N$1:N6), "")} -> 45.631068 | P7: =IF(C7=1, 0, IF(AND(A7=A6, J7=J6), ROUND(MAX(0, (D7-E6)*24), 2), 0)) -> 0 | Q7: Theory | R7: No | S7: =IF(OR(ISNUMBER(SEARCH("Guest", F7)), ISNUMBER(SEARCH("Hands-on", F7)), ISNUMBER(SEARCH("Project", F7)), B7="Friday"), "Yes", "No") -> No | T7: No | U7: =IF(MONTH(A7)=6, IF(DAY(A7)<20, "Sunny", "Cloudy"), IF(OR(MONTH(A7)=7, MONTH(A7)=8), "Rainy", "Sunny")) -> Sunny | V7: No | W7: {=_xlfn.IFS( OR(F7="Selenium (Hands-on)",F7="Guest Lecture: HR Interview"),6, OR(F7="Soft Skill",F7="Soft Skill (Examination)",F7="AWS Training",F7="AWS Session"),7, OR(ISNUMBER(SEARCH("MAD",F7)),ISNUMBER(SEARCH("STQA",F7)),F7="CI/CD Session"),8, OR(ISNUMBER(SEARCH("Cloud",F7)),F7="Industry Readiness Program",ISNUMBER(SEARCH("Talenlio",F7))),9, OR(ISNUMBER(SEARCH("Innovation",F7)),F7="Mini Project"),10, OR(ISNUMBER(SEARCH("Data Science",F7)),ISNUMBER(SEARCH("DS",F7))),11, ISNUMBER(SEARCH("Generative AI",F7)),12 =_xlfn.IFS( OR(F7="Selenium (Hands-on)",F7="Guest Lecture: HR Interview"),6, OR(F7="Soft Skill",F7="Soft Skill (Examination)",F7="AWS Training",F7="AWS Session"),7, OR(ISNUMBER(SEARCH("MAD",F7)),ISNUMBER(SEARCH("STQA",F7)),F7="CI/CD Session"),8, OR(ISNUMBER(SEARCH("Cloud",F7)),F7="Industry Readiness Program",ISNUMBER(SEARCH("Talenlio",F7))),9, OR(ISNUMBER(SEARCH("Innovation",F7)),F7="Mini Project"),10, OR(ISNUMBER(SEARCH("Data Science",F7)),ISNUMBER(SEARCH("DS",F7))),11, ISNUMBER(SEARCH("Generative AI",F7)),12 =_xlfn.IFS( OR(F7="Selenium (Hands-on)",F7="Guest Lecture: HR Interview"),6, OR(F7="Soft Skill",F7="Soft Skill (Examination)",F7="AWS Training",F7="AWS Session"),7, OR(ISNUMBER(SEARCH("MAD",F7)),ISNUMBER(SEARCH("STQA",F7)),F7="CI/CD Session"),8, OR(ISNUMBER(SEARCH("Cloud",F7)),F7="Industry Readiness Program",ISNUMBER(SEARCH("Talenlio",F7))),9, OR(ISNUMBER(SEARCH("Innovation",F7)),F7="Mini Project"),10, OR(ISNUMBER(SEARCH("Data Science",F7)),ISNUMBER(SEARCH("DS",F7))),11, ISNUMBER(SEARCH("Generative AI",F7)),12 =_xlfn.IFS( OR(F7="Selenium (Hands-on)",F7="Guest Lecture: HR Interview"),6, OR(F7="Soft Skill",F7="Soft Skill (Examination)",F7="AWS Training",F7="AWS Session"),7, OR(ISNUMBER(SEARCH("MAD",F7)),ISNUMBER(SEARCH("STQA",F7)),F7="CI/CD Session"),8, OR(ISNUMBER(SEARCH("Cloud",F7)),F7="Industry Readiness Program",ISNUMBER(SEARCH("Talenlio",F7))),9, OR(ISNUMBER(SEARCH("Innovation",F7)),F7="Mini Project"),10, OR(ISNUMBER(SEARCH("Data Science",F7)),ISNUMBER(SEARCH("DS",F7))),11, ISNUMBER(SEARCH("Generative AI",F7)),12 ))))} -> 7 | X7: 1 | Y7: 2 | Z7: Morning
A8: 46189 | B8: Tuesday | C8: 3 | D8: 0.5625 | E8: 0.60416667 | F8: CI/CD Session | G8: DB | H8: III | I8: MCA | J8: A | K8: Lab | L8: 103 | M8: =RANDBETWEEN(40,103) -> 66 | N8: =IF(OR(L8="",M8=""),"",M8/L8*100) -> 64.07767 | O8: 84.328574 | P8: =IF(C8=1, 0, IF(AND(A8=A7, J8=J7), ROUND(MAX(0, (D8-E7)*24), 2), 0)) -> 2.25 | Q8: Practical | R8: No | S8: =IF(OR(ISNUMBER(SEARCH("Guest", F8)), ISNUMBER(SEARCH("Hands-on", F8)), ISNUMBER(SEARCH("Project", F8)), B8="Friday"), "Yes", "No") -> No | T8: No | U8: =IF(MONTH(A8)=6, IF(DAY(A8)<20, "Sunny", "Cloudy"), IF(OR(MONTH(A8)=7, MONTH(A8)=8), "Rainy", "Sunny")) -> Sunny | V8: No | W8: {=_xlfn.IFS( OR(F8="Selenium (Hands-on)",F8="Guest Lecture: HR Interview"),6, OR(F8="Soft Skill",F8="Soft Skill (Examination)",F8="AWS Training",F8="AWS Session"),7, OR(ISNUMBER(SEARCH("MAD",F8)),ISNUMBER(SEARCH("STQA",F8)),F8="CI/CD Session"),8, OR(ISNUMBER(SEARCH("Cloud",F8)),F8="Industry Readiness Program",ISNUMBER(SEARCH("Talenlio",F8))),9, OR(ISNUMBER(SEARCH("Innovation",F8)),F8="Mini Project"),10, OR(ISNUMBER(SEARCH("Data Science",F8)),ISNUMBER(SEARCH("DS",F8))),11, ISNUMBER(SEARCH("Generative AI",F8)),12 =_xlfn.IFS( OR(F8="Selenium (Hands-on)",F8="Guest Lecture: HR Interview"),6, OR(F8="Soft Skill",F8="Soft Skill (Examination)",F8="AWS Training",F8="AWS Session"),7, OR(ISNUMBER(SEARCH("MAD",F8)),ISNUMBER(SEARCH("STQA",F8)),F8="CI/CD Session"),8, OR(ISNUMBER(SEARCH("Cloud",F8)),F8="Industry Readiness Program",ISNUMBER(SEARCH("Talenlio",F8))),9, OR(ISNUMBER(SEARCH("Innovation",F8)),F8="Mini Project"),10, OR(ISNUMBER(SEARCH("Data Science",F8)),ISNUMBER(SEARCH("DS",F8))),11, ISNUMBER(SEARCH("Generative AI",F8)),12 =_xlfn.IFS( OR(F8="Selenium (Hands-on)",F8="Guest Lecture: HR Interview"),6, OR(F8="Soft Skill",F8="Soft Skill (Examination)",F8="AWS Training",F8="AWS Session"),7, OR(ISNUMBER(SEARCH("MAD",F8)),ISNUMBER(SEARCH("STQA",F8)),F8="CI/CD Session"),8, OR(ISNUMBER(SEARCH("Cloud",F8)),F8="Industry Readiness Program",ISNUMBER(SEARCH("Talenlio",F8))),9, OR(ISNUMBER(SEARCH("Innovation",F8)),F8="Mini Project"),10, OR(ISNUMBER(SEARCH("Data Science",F8)),ISNUMBER(SEARCH("DS",F8))),11, ISNUMBER(SEARCH("Generative AI",F8)),12 =_xlfn.IFS( OR(F8="Selenium (Hands-on)",F8="Guest Lecture: HR Interview"),6, OR(F8="Soft Skill",F8="Soft Skill (Examination)",F8="AWS Training",F8="AWS Session"),7, OR(ISNUMBER(SEARCH("MAD",F8)),ISNUMBER(SEARCH("STQA",F8)),F8="CI/CD Session"),8, OR(ISNUMBER(SEARCH("Cloud",F8)),F8="Industry Readiness Program",ISNUMBER(SEARCH("Talenlio",F8))),9, OR(ISNUMBER(SEARCH("Innovation",F8)),F8="Mini Project"),10, OR(ISNUMBER(SEARCH("Data Science",F8)),ISNUMBER(SEARCH("DS",F8))),11, ISNUMBER(SEARCH("Generative AI",F8)),12 ))))} -> 8 | X8: 1 | Y8: 2 | Z8: Afternoon
A9: 46189 | B9: Tuesday | C9: 4 | D9: 0.60416667 | E9: 0.64583333 | F9: CI/CD Session | G9: DB | H9: III | I9: MCA | J9: A | K9: Lab | L9: 103 | M9: =RANDBETWEEN(40,103) -> 101 | N9: =IF(OR(L9="",M9=""),"",M9/L9*100) -> 98.058252 | O9: {=IFERROR(LOOKUP(2, 1/((F$1:F8=F9)*(J$1:J8=J9)*(ROW(F$1:F8)<ROW(F9))), N$1:N8), "")} -> 64.07767 | P9: =IF(C9=1, 0, IF(AND(A9=A8, J9=J8), ROUND(MAX(0, (D9-E8)*24), 2), 0)) -> 0 | Q9: Practical | R9: No | S9: =IF(OR(ISNUMBER(SEARCH("Guest", F9)), ISNUMBER(SEARCH("Hands-on", F9)), ISNUMBER(SEARCH("Project", F9)), B9="Friday"), "Yes", "No") -> No | T9: No | U9: =IF(MONTH(A9)=6, IF(DAY(A9)<20, "Sunny", "Cloudy"), IF(OR(MONTH(A9)=7, MONTH(A9)=8), "Rainy", "Sunny")) -> Sunny | V9: No | W9: {=_xlfn.IFS( OR(F9="Selenium (Hands-on)",F9="Guest Lecture: HR Interview"),6, OR(F9="Soft Skill",F9="Soft Skill (Examination)",F9="AWS Training",F9="AWS Session"),7, OR(ISNUMBER(SEARCH("MAD",F9)),ISNUMBER(SEARCH("STQA",F9)),F9="CI/CD Session"),8, OR(ISNUMBER(SEARCH("Cloud",F9)),F9="Industry Readiness Program",ISNUMBER(SEARCH("Talenlio",F9))),9, OR(ISNUMBER(SEARCH("Innovation",F9)),F9="Mini Project"),10, OR(ISNUMBER(SEARCH("Data Science",F9)),ISNUMBER(SEARCH("DS",F9))),11, ISNUMBER(SEARCH("Generative AI",F9)),12 =_xlfn.IFS( OR(F9="Selenium (Hands-on)",F9="Guest Lecture: HR Interview"),6, OR(F9="Soft Skill",F9="Soft Skill (Examination)",F9="AWS Training",F9="AWS Session"),7, OR(ISNUMBER(SEARCH("MAD",F9)),ISNUMBER(SEARCH("STQA",F9)),F9="CI/CD Session"),8, OR(ISNUMBER(SEARCH("Cloud",F9)),F9="Industry Readiness Program",ISNUMBER(SEARCH("Talenlio",F9))),9, OR(ISNUMBER(SEARCH("Innovation",F9)),F9="Mini Project"),10, OR(ISNUMBER(SEARCH("Data Science",F9)),ISNUMBER(SEARCH("DS",F9))),11, ISNUMBER(SEARCH("Generative AI",F9)),12 =_xlfn.IFS( OR(F9="Selenium (Hands-on)",F9="Guest Lecture: HR Interview"),6, OR(F9="Soft Skill",F9="Soft Skill (Examination)",F9="AWS Training",F9="AWS Session"),7, OR(ISNUMBER(SEARCH("MAD",F9)),ISNUMBER(SEARCH("STQA",F9)),F9="CI/CD Session"),8, OR(ISNUMBER(SEARCH("Cloud",F9)),F9="Industry Readiness Program",ISNUMBER(SEARCH("Talenlio",F9))),9, OR(ISNUMBER(SEARCH("Innovation",F9)),F9="Mini Project"),10, OR(ISNUMBER(SEARCH("Data Science",F9)),ISNUMBER(SEARCH("DS",F9))),11, ISNUMBER(SEARCH("Generative AI",F9)),12 =_xlfn.IFS( OR(F9="Selenium (Hands-on)",F9="Guest Lecture: HR Interview"),6, OR(F9="Soft Skill",F9="Soft Skill (Examination)",F9="AWS Training",F9="AWS Session"),7, OR(ISNUMBER(SEARCH("MAD",F9)),ISNUMBER(SEARCH("STQA",F9)),F9="CI/CD Session"),8, OR(ISNUMBER(SEARCH("Cloud",F9)),F9="Industry Readiness Program",ISNUMBER(SEARCH("Talenlio",F9))),9, OR(ISNUMBER(SEARCH("Innovation",F9)),F9="Mini Project"),10, OR(ISNUMBER(SEARCH("Data Science",F9)),ISNUMBER(SEARCH("DS",F9))),11, ISNUMBER(SEARCH("Generative AI",F9)),12 ))))} -> 8 | X9: 1 | Y9: 2 | Z9: Afternoon
A10: 46190 | B10: Wednesday | C10: 1 | D10: 0.38541667 | E10: 0.42708333 | F10: Soft Skill | G10: SD | H10: III | I10: MCA | J10: A | K10: Seminar Hall | L10: 103 | M10: =RANDBETWEEN(40,103) -> 97 | N10: =IF(OR(L10="",M10=""),"",M10/L10*100) -> 94.174757 | O10: {=IFERROR(LOOKUP(2, 1/((F$1:F9=F10)*(J$1:J9=J10)*(ROW(F$1:F9)<ROW(F10))), N$1:N9), "")} -> 65.048544 | P10: =IF(C10=1, 0, IF(AND(A10=A9, J10=J9), ROUND(MAX(0, (D10-E9)*24), 2), 0)) -> 0 | Q10: Theory | R10: No | S10: =IF(OR(ISNUMBER(SEARCH("Guest", F10)), ISNUMBER(SEARCH("Hands-on", F10)), ISNUMBER(SEARCH("Project", F10)), B10="Friday"), "Yes", "No") -> No | T10: No | U10: =IF(MONTH(A10)=6, IF(DAY(A10)<20, "Sunny", "Cloudy"), IF(OR(MONTH(A10)=7, MONTH(A10)=8), "Rainy", "Sunny")) -> Sunny | V10: No | W10: {=_xlfn.IFS( OR(F10="Selenium (Hands-on)",F10="Guest Lecture: HR Interview"),6, OR(F10="Soft Skill",F10="Soft Skill (Examination)",F10="AWS Training",F10="AWS Session"),7, OR(ISNUMBER(SEARCH("MAD",F10)),ISNUMBER(SEARCH("STQA",F10)),F10="CI/CD Session"),8, OR(ISNUMBER(SEARCH("Cloud",F10)),F10="Industry Readiness Program",ISNUMBER(SEARCH("Talenlio",F10))),9, OR(ISNUMBER(SEARCH("Innovation",F10)),F10="Mini Project"),10, OR(ISNUMBER(SEARCH("Data Science",F10)),ISNUMBER(SEARCH("DS",F10))),11, ISNUMBER(SEARCH("Generative AI",F10)),12 =_xlfn.IFS( OR(F10="Selenium (Hands-on)",F10="Guest Lecture: HR Interview"),6, OR(F10="Soft Skill",F10="Soft Skill (Examination)",F10="AWS Training",F10="AWS Session"),7, OR(ISNUMBER(SEARCH("MAD",F10)),ISNUMBER(SEARCH("STQA",F10)),F10="CI/CD Session"),8, OR(ISNUMBER(SEARCH("Cloud",F10)),F10="Industry Readiness Program",ISNUMBER(SEARCH("Talenlio",F10))),9, OR(ISNUMBER(SEARCH("Innovation",F10)),F10="Mini Project"),10, OR(ISNUMBER(SEARCH("Data Science",F10)),ISNUMBER(SEARCH("DS",F10))),11, ISNUMBER(SEARCH("Generative AI",F10)),12 =_xlfn.IFS( OR(F10="Selenium (Hands-on)",F10="Guest Lecture: HR Interview"),6, OR(F10="Soft Skill",F10="Soft Skill (Examination)",F10="AWS Training",F10="AWS Session"),7, OR(ISNUMBER(SEARCH("MAD",F10)),ISNUMBER(SEARCH("STQA",F10)),F10="CI/CD Session"),8, OR(ISNUMBER(SEARCH("Cloud",F10)),F10="Industry Readiness Program",ISNUMBER(SEARCH("Talenlio",F10))),9, OR(ISNUMBER(SEARCH("Innovation",F10)),F10="Mini Project"),10, OR(ISNUMBER(SEARCH("Data Science",F10)),ISNUMBER(SEARCH("DS",F10))),11, ISNUMBER(SEARCH("Generative AI",F10)),12 =_xlfn.IFS( OR(F10="Selenium (Hands-on)",F10="Guest Lecture: HR Interview"),6, OR(F10="Soft Skill",F10="Soft Skill (Examination)",F10="AWS Training",F10="AWS Session"),7, OR(ISNUMBER(SEARCH("MAD",F10)),ISNUMBER(SEARCH("STQA",F10)),F10="CI/CD Session"),8, OR(ISNUMBER(SEARCH("Cloud",F10)),F10="Industry Readiness Program",ISNUMBER(SEARCH("Talenlio",F10))),9, OR(ISNUMBER(SEARCH("Innovation",F10)),F10="Mini Project"),10, OR(ISNUMBER(SEARCH("Data Science",F10)),ISNUMBER(SEARCH("DS",F10))),11, ISNUMBER(SEARCH("Generative AI",F10)),12 ))))} -> 7 | X10: 1 | Y10: 3 | Z10: Morning
A11: 46190 | B11: Wednesday | C11: 2 | D11: 0.42708333 | E11: 0.46875 | F11: Soft Skill | G11: SD | H11: III | I11: MCA | J11: A | K11: Seminar Hall | L11: 103 | M11: =RANDBETWEEN(40,103) -> 49 | N11: =IF(OR(L11="",M11=""),"",M11/L11*100) -> 47.572816 | O11: {=IFERROR(LOOKUP(2, 1/((F$1:F10=F11)*(J$1:J10=J11)*(ROW(F$1:F10)<ROW(F11))), N$1:N10), "")} -> 94.174757 | P11: =IF(C11=1, 0, IF(AND(A11=A10, J11=J10), ROUND(MAX(0, (D11-E10)*24), 2), 0)) -> 0 | Q11: Theory | R11: No | S11: =IF(OR(ISNUMBER(SEARCH("Guest", F11)), ISNUMBER(SEARCH("Hands-on", F11)), ISNUMBER(SEARCH("Project", F11)), B11="Friday"), "Yes", "No") -> No | T11: No | U11: =IF(MONTH(A11)=6, IF(DAY(A11)<20, "Sunny", "Cloudy"), IF(OR(MONTH(A11)=7, MONTH(A11)=8), "Rainy", "Sunny")) -> Sunny | V11: No | W11: {=_xlfn.IFS( OR(F11="Selenium (Hands-on)",F11="Guest Lecture: HR Interview"),6, OR(F11="Soft Skill",F11="Soft Skill (Examination)",F11="AWS Training",F11="AWS Session"),7, OR(ISNUMBER(SEARCH("MAD",F11)),ISNUMBER(SEARCH("STQA",F11)),F11="CI/CD Session"),8, OR(ISNUMBER(SEARCH("Cloud",F11)),F11="Industry Readiness Program",ISNUMBER(SEARCH("Talenlio",F11))),9, OR(ISNUMBER(SEARCH("Innovation",F11)),F11="Mini Project"),10, OR(ISNUMBER(SEARCH("Data Science",F11)),ISNUMBER(SEARCH("DS",F11))),11, ISNUMBER(SEARCH("Generative AI",F11)),12 =_xlfn.IFS( OR(F11="Selenium (Hands-on)",F11="Guest Lecture: HR Interview"),6, OR(F11="Soft Skill",F11="Soft Skill (Examination)",F11="AWS Training",F11="AWS Session"),7, OR(ISNUMBER(SEARCH("MAD",F11)),ISNUMBER(SEARCH("STQA",F11)),F11="CI/CD Session"),8, OR(ISNUMBER(SEARCH("Cloud",F11)),F11="Industry Readiness Program",ISNUMBER(SEARCH("Talenlio",F11))),9, OR(ISNUMBER(SEARCH("Innovation",F11)),F11="Mini Project"),10, OR(ISNUMBER(SEARCH("Data Science",F11)),ISNUMBER(SEARCH("DS",F11))),11, ISNUMBER(SEARCH("Generative AI",F11)),12 =_xlfn.IFS( OR(F11="Selenium (Hands-on)",F11="Guest Lecture: HR Interview"),6, OR(F11="Soft Skill",F11="Soft Skill (Examination)",F11="AWS Training",F11="AWS Session"),7, OR(ISNUMBER(SEARCH("MAD",F11)),ISNUMBER(SEARCH("STQA",F11)),F11="CI/CD Session"),8, OR(ISNUMBER(SEARCH("Cloud",F11)),F11="Industry Readiness Program",ISNUMBER(SEARCH("Talenlio",F11))),9, OR(ISNUMBER(SEARCH("Innovation",F11)),F11="Mini Project"),10, OR(ISNUMBER(SEARCH("Data Science",F11)),ISNUMBER(SEARCH("DS",F11))),11, ISNUMBER(SEARCH("Generative AI",F11)),12 =_xlfn.IFS( OR(F11="Selenium (Hands-on)",F11="Guest Lecture: HR Interview"),6, OR(F11="Soft Skill",F11="Soft Skill (Examination)",F11="AWS Training",F11="AWS Session"),7, OR(ISNUMBER(SEARCH("MAD",F11)),ISNUMBER(SEARCH("STQA",F11)),F11="CI/CD Session"),8, OR(ISNUMBER(SEARCH("Cloud",F11)),F11="Industry Readiness Program",ISNUMBER(SEARCH("Talenlio",F11))),9, OR(ISNUMBER(SEARCH("Innovation",F11)),F11="Mini Project"),10, OR(ISNUMBER(SEARCH("Data Science",F11)),ISNUMBER(SEARCH("DS",F11))),11, ISNUMBER(SEARCH("Generative AI",F11)),12 ))))} -> 7 | X11: 1 | Y11: 3 | Z11: Morning
A12: 46190 | B12: Wednesday | C12: 3 | D12: 0.5625 | E12: 0.60416667 | F12: CI/CD Session | G12: DB | H12: III | I12: MCA | J12: A | K12: Lab | L12: 103 | M12: =RANDBETWEEN(40,103) -> 78 | N12: =IF(OR(L12="",M12=""),"",M12/L12*100) -> 75.728155 | O12: {=IFERROR(LOOKUP(2, 1/((F$1:F11=F12)*(J$1:J11=J12)*(ROW(F$1:F11)<ROW(F12))), N$1:N11), "")} -> 98.058252 | P12: =IF(C12=1, 0, IF(AND(A12=A11, J12=J11), ROUND(MAX(0, (D12-E11)*24), 2), 0)) -> 2.25 | Q12: Practical | R12: No | S12: =IF(OR(ISNUMBER(SEARCH("Guest", F12)), ISNUMBER(SEARCH("Hands-on", F12)), ISNUMBER(SEARCH("Project", F12)), B12="Friday"), "Yes", "No") -> No | T12: No | U12: =IF(MONTH(A12)=6, IF(DAY(A12)<20, "Sunny", "Cloudy"), IF(OR(MONTH(A12)=7, MONTH(A12)=8), "Rainy", "Sunny")) -> Sunny | V12: No | W12: {=_xlfn.IFS( OR(F12="Selenium (Hands-on)",F12="Guest Lecture: HR Interview"),6, OR(F12="Soft Skill",F12="Soft Skill (Examination)",F12="AWS Training",F12="AWS Session"),7, OR(ISNUMBER(SEARCH("MAD",F12)),ISNUMBER(SEARCH("STQA",F12)),F12="CI/CD Session"),8, OR(ISNUMBER(SEARCH("Cloud",F12)),F12="Industry Readiness Program",ISNUMBER(SEARCH("Talenlio",F12))),9, OR(ISNUMBER(SEARCH("Innovation",F12)),F12="Mini Project"),10, OR(ISNUMBER(SEARCH("Data Science",F12)),ISNUMBER(SEARCH("DS",F12))),11, ISNUMBER(SEARCH("Generative AI",F12)),12 =_xlfn.IFS( OR(F12="Selenium (Hands-on)",F12="Guest Lecture: HR Interview"),6, OR(F12="Soft Skill",F12="Soft Skill (Examination)",F12="AWS Training",F12="AWS Session"),7, OR(ISNUMBER(SEARCH("MAD",F12)),ISNUMBER(SEARCH("STQA",F12)),F12="CI/CD Session"),8, OR(ISNUMBER(SEARCH("Cloud",F12)),F12="Industry Readiness Program",ISNUMBER(SEARCH("Talenlio",F12))),9, OR(ISNUMBER(SEARCH("Innovation",F12)),F12="Mini Project"),10, OR(ISNUMBER(SEARCH("Data Science",F12)),ISNUMBER(SEARCH("DS",F12))),11, ISNUMBER(SEARCH("Generative AI",F12)),12 =_xlfn.IFS( OR(F12="Selenium (Hands-on)",F12="Guest Lecture: HR Interview"),6, OR(F12="Soft Skill",F12="Soft Skill (Examination)",F12="AWS Training",F12="AWS Session"),7, OR(ISNUMBER(SEARCH("MAD",F12)),ISNUMBER(SEARCH("STQA",F12)),F12="CI/CD Session"),8, OR(ISNUMBER(SEARCH("Cloud",F12)),F12="Industry Readiness Program",ISNUMBER(SEARCH("Talenlio",F12))),9, OR(ISNUMBER(SEARCH("Innovation",F12)),F12="Mini Project"),10, OR(ISNUMBER(SEARCH("Data Science",F12)),ISNUMBER(SEARCH("DS",F12))),11, ISNUMBER(SEARCH("Generative AI",F12)),12 =_xlfn.IFS( OR(F12="Selenium (Hands-on)",F12="Guest Lecture: HR Interview"),6, OR(F12="Soft Skill",F12="Soft Skill (Examination)",F12="AWS Training",F12="AWS Session"),7, OR(ISNUMBER(SEARCH("MAD",F12)),ISNUMBER(SEARCH("STQA",F12)),F12="CI/CD Session"),8, OR(ISNUMBER(SEARCH("Cloud",F12)),F12="Industry Readiness Program",ISNUMBER(SEARCH("Talenlio",F12))),9, OR(ISNUMBER(SEARCH("Innovation",F12)),F12="Mini Project"),10, OR(ISNUMBER(SEARCH("Data Science",F12)),ISNUMBER(SEARCH("DS",F12))),11, ISNUMBER(SEARCH("Generative AI",F12)),12 ))))} -> 8 | X12: 1 | Y12: 3 | Z12: Afternoon
A13: 46190 | B13: Wednesday | C13: 4 | D13: 0.60416667 | E13: 0.64583333 | F13: CI/CD Session | G13: DB | H13: III | I13: MCA | J13: A | K13: Lab | L13: 103 | M13: =RANDBETWEEN(40,103) -> 44 | N13: =IF(OR(L13="",M13=""),"",M13/L13*100) -> 42.718447 | O13: {=IFERROR(LOOKUP(2, 1/((F$1:F12=F13)*(J$1:J12=J13)*(ROW(F$1:F12)<ROW(F13))), N$1:N12), "")} -> 75.728155 | P13: =IF(C13=1, 0, IF(AND(A13=A12, J13=J12), ROUND(MAX(0, (D13-E12)*24), 2), 0)) -> 0 | Q13: Practical | R13: No | S13: =IF(OR(ISNUMBER(SEARCH("Guest", F13)), ISNUMBER(SEARCH("Hands-on", F13)), ISNUMBER(SEARCH("Project", F13)), B13="Friday"), "Yes", "No") -> No | T13: No | U13: =IF(MONTH(A13)=6, IF(DAY(A13)<20, "Sunny", "Cloudy"), IF(OR(MONTH(A13)=7, MONTH(A13)=8), "Rainy", "Sunny")) -> Sunny | V13: No | W13: {=_xlfn.IFS( OR(F13="Selenium (Hands-on)",F13="Guest Lecture: HR Interview"),6, OR(F13="Soft Skill",F13="Soft Skill (Examination)",F13="AWS Training",F13="AWS Session"),7, OR(ISNUMBER(SEARCH("MAD",F13)),ISNUMBER(SEARCH("STQA",F13)),F13="CI/CD Session"),8, OR(ISNUMBER(SEARCH("Cloud",F13)),F13="Industry Readiness Program",ISNUMBER(SEARCH("Talenlio",F13))),9, OR(ISNUMBER(SEARCH("Innovation",F13)),F13="Mini Project"),10, OR(ISNUMBER(SEARCH("Data Science",F13)),ISNUMBER(SEARCH("DS",F13))),11, ISNUMBER(SEARCH("Generative AI",F13)),12 =_xlfn.IFS( OR(F13="Selenium (Hands-on)",F13="Guest Lecture: HR Interview"),6, OR(F13="Soft Skill",F13="Soft Skill (Examination)",F13="AWS Training",F13="AWS Session"),7, OR(ISNUMBER(SEARCH("MAD",F13)),ISNUMBER(SEARCH("STQA",F13)),F13="CI/CD Session"),8, OR(ISNUMBER(SEARCH("Cloud",F13)),F13="Industry Readiness Program",ISNUMBER(SEARCH("Talenlio",F13))),9, OR(ISNUMBER(SEARCH("Innovation",F13)),F13="Mini Project"),10, OR(ISNUMBER(SEARCH("Data Science",F13)),ISNUMBER(SEARCH("DS",F13))),11, ISNUMBER(SEARCH("Generative AI",F13)),12 =_xlfn.IFS( OR(F13="Selenium (Hands-on)",F13="Guest Lecture: HR Interview"),6, OR(F13="Soft Skill",F13="Soft Skill (Examination)",F13="AWS Training",F13="AWS Session"),7, OR(ISNUMBER(SEARCH("MAD",F13)),ISNUMBER(SEARCH("STQA",F13)),F13="CI/CD Session"),8, OR(ISNUMBER(SEARCH("Cloud",F13)),F13="Industry Readiness Program",ISNUMBER(SEARCH("Talenlio",F13))),9, OR(ISNUMBER(SEARCH("Innovation",F13)),F13="Mini Project"),10, OR(ISNUMBER(SEARCH("Data Science",F13)),ISNUMBER(SEARCH("DS",F13))),11, ISNUMBER(SEARCH("Generative AI",F13)),12 =_xlfn.IFS( OR(F13="Selenium (Hands-on)",F13="Guest Lecture: HR Interview"),6, OR(F13="Soft Skill",F13="Soft Skill (Examination)",F13="AWS Training",F13="AWS Session"),7, OR(ISNUMBER(SEARCH("MAD",F13)),ISNUMBER(SEARCH("STQA",F13)),F13="CI/CD Session"),8, OR(ISNUMBER(SEARCH("Cloud",F13)),F13="Industry Readiness Program",ISNUMBER(SEARCH("Talenlio",F13))),9, OR(ISNUMBER(SEARCH("Innovation",F13)),F13="Mini Project"),10, OR(ISNUMBER(SEARCH("Data Science",F13)),ISNUMBER(SEARCH("DS",F13))),11, ISNUMBER(SEARCH("Generative AI",F13)),12 ))))} -> 8 | X13: 1 | Y13: 3 | Z13: Afternoon
A14: 46191 | B14: Thursday | C14: 1 | D14: 0.38541667 | E14: 0.42708333 | F14: Soft Skill | G14: SD | H14: III | I14: MCA | J14: A | K14: Seminar Hall | L14: 103 | M14: =RANDBETWEEN(40,103) -> 41 | N14: =IF(OR(L14="",M14=""),"",M14/L14*100) -> 39.805825 | O14: {=IFERROR(LOOKUP(2, 1/((F$1:F13=F14)*(J$1:J13=J14)*(ROW(F$1:F13)<ROW(F14))), N$1:N13), "")} -> 47.572816 | P14: =IF(C14=1, 0, IF(AND(A14=A13, J14=J13), ROUND(MAX(0, (D14-E13)*24), 2), 0)) -> 0 | Q14: Theory | R14: No | S14: =IF(OR(ISNUMBER(SEARCH("Guest", F14)), ISNUMBER(SEARCH("Hands-on", F14)), ISNUMBER(SEARCH("Project", F14)), B14="Friday"), "Yes", "No") -> No | T14: No | U14: =IF(MONTH(A14)=6, IF(DAY(A14)<20, "Sunny", "Cloudy"), IF(OR(MONTH(A14)=7, MONTH(A14)=8), "Rainy", "Sunny")) -> Sunny | V14: No | W14: {=_xlfn.IFS( OR(F14="Selenium (Hands-on)",F14="Guest Lecture: HR Interview"),6, OR(F14="Soft Skill",F14="Soft Skill (Examination)",F14="AWS Training",F14="AWS Session"),7, OR(ISNUMBER(SEARCH("MAD",F14)),ISNUMBER(SEARCH("STQA",F14)),F14="CI/CD Session"),8, OR(ISNUMBER(SEARCH("Cloud",F14)),F14="Industry Readiness Program",ISNUMBER(SEARCH("Talenlio",F14))),9, OR(ISNUMBER(SEARCH("Innovation",F14)),F14="Mini Project"),10, OR(ISNUMBER(SEARCH("Data Science",F14)),ISNUMBER(SEARCH("DS",F14))),11, ISNUMBER(SEARCH("Generative AI",F14)),12 =_xlfn.IFS( OR(F14="Selenium (Hands-on)",F14="Guest Lecture: HR Interview"),6, OR(F14="Soft Skill",F14="Soft Skill (Examination)",F14="AWS Training",F14="AWS Session"),7, OR(ISNUMBER(SEARCH("MAD",F14)),ISNUMBER(SEARCH("STQA",F14)),F14="CI/CD Session"),8, OR(ISNUMBER(SEARCH("Cloud",F14)),F14="Industry Readiness Program",ISNUMBER(SEARCH("Talenlio",F14))),9, OR(ISNUMBER(SEARCH("Innovation",F14)),F14="Mini Project"),10, OR(ISNUMBER(SEARCH("Data Science",F14)),ISNUMBER(SEARCH("DS",F14))),11, ISNUMBER(SEARCH("Generative AI",F14)),12 =_xlfn.IFS( OR(F14="Selenium (Hands-on)",F14="Guest Lecture: HR Interview"),6, OR(F14="Soft Skill",F14="Soft Skill (Examination)",F14="AWS Training",F14="AWS Session"),7, OR(ISNUMBER(SEARCH("MAD",F14)),ISNUMBER(SEARCH("STQA",F14)),F14="CI/CD Session"),8, OR(ISNUMBER(SEARCH("Cloud",F14)),F14="Industry Readiness Program",ISNUMBER(SEARCH("Talenlio",F14))),9, OR(ISNUMBER(SEARCH("Innovation",F14)),F14="Mini Project"),10, OR(ISNUMBER(SEARCH("Data Science",F14)),ISNUMBER(SEARCH("DS",F14))),11, ISNUMBER(SEARCH("Generative AI",F14)),12 =_xlfn.IFS( OR(F14="Selenium (Hands-on)",F14="Guest Lecture: HR Interview"),6, OR(F14="Soft Skill",F14="Soft Skill (Examination)",F14="AWS Training",F14="AWS Session"),7, OR(ISNUMBER(SEARCH("MAD",F14)),ISNUMBER(SEARCH("STQA",F14)),F14="CI/CD Session"),8, OR(ISNUMBER(SEARCH("Cloud",F14)),F14="Industry Readiness Program",ISNUMBER(SEARCH("Talenlio",F14))),9, OR(ISNUMBER(SEARCH("Innovation",F14)),F14="Mini Project"),10, OR(ISNUMBER(SEARCH("Data Science",F14)),ISNUMBER(SEARCH("DS",F14))),11, ISNUMBER(SEARCH("Generative AI",F14)),12 ))))} -> 7 | X14: 1 | Y14: 4 | Z14: Morning
A15: 46191 | B15: Thursday | C15: 2 | D15: 0.42708333 | E15: 0.46875 | F15: Soft Skill | G15: SD | H15: III | I15: MCA | J15: A | K15: Seminar Hall | L15: 103 | M15: =RANDBETWEEN(40,103) -> 69 | N15: =IF(OR(L15="",M15=""),"",M15/L15*100) -> 66.990291 | O15: {=IFERROR(LOOKUP(2, 1/((F$1:F14=F15)*(J$1:J14=J15)*(ROW(F$1:F14)<ROW(F15))), N$1:N14), "")} -> 39.805825 | P15: =IF(C15=1, 0, IF(AND(A15=A14, J15=J14), ROUND(MAX(0, (D15-E14)*24), 2), 0)) -> 0 | Q15: Theory | R15: No | S15: =IF(OR(ISNUMBER(SEARCH("Guest", F15)), ISNUMBER(SEARCH("Hands-on", F15)), ISNUMBER(SEARCH("Project", F15)), B15="Friday"), "Yes", "No") -> No | T15: No | U15: =IF(MONTH(A15)=6, IF(DAY(A15)<20, "Sunny", "Cloudy"), IF(OR(MONTH(A15)=7, MONTH(A15)=8), "Rainy", "Sunny")) -> Sunny | V15: No | W15: {=_xlfn.IFS( OR(F15="Selenium (Hands-on)",F15="Guest Lecture: HR Interview"),6, OR(F15="Soft Skill",F15="Soft Skill (Examination)",F15="AWS Training",F15="AWS Session"),7, OR(ISNUMBER(SEARCH("MAD",F15)),ISNUMBER(SEARCH("STQA",F15)),F15="CI/CD Session"),8, OR(ISNUMBER(SEARCH("Cloud",F15)),F15="Industry Readiness Program",ISNUMBER(SEARCH("Talenlio",F15))),9, OR(ISNUMBER(SEARCH("Innovation",F15)),F15="Mini Project"),10, OR(ISNUMBER(SEARCH("Data Science",F15)),ISNUMBER(SEARCH("DS",F15))),11, ISNUMBER(SEARCH("Generative AI",F15)),12 =_xlfn.IFS( OR(F15="Selenium (Hands-on)",F15="Guest Lecture: HR Interview"),6, OR(F15="Soft Skill",F15="Soft Skill (Examination)",F15="AWS Training",F15="AWS Session"),7, OR(ISNUMBER(SEARCH("MAD",F15)),ISNUMBER(SEARCH("STQA",F15)),F15="CI/CD Session"),8, OR(ISNUMBER(SEARCH("Cloud",F15)),F15="Industry Readiness Program",ISNUMBER(SEARCH("Talenlio",F15))),9, OR(ISNUMBER(SEARCH("Innovation",F15)),F15="Mini Project"),10, OR(ISNUMBER(SEARCH("Data Science",F15)),ISNUMBER(SEARCH("DS",F15))),11, ISNUMBER(SEARCH("Generative AI",F15)),12 =_xlfn.IFS( OR(F15="Selenium (Hands-on)",F15="Guest Lecture: HR Interview"),6, OR(F15="Soft Skill",F15="Soft Skill (Examination)",F15="AWS Training",F15="AWS Session"),7, OR(ISNUMBER(SEARCH("MAD",F15)),ISNUMBER(SEARCH("STQA",F15)),F15="CI/CD Session"),8, OR(ISNUMBER(SEARCH("Cloud",F15)),F15="Industry Readiness Program",ISNUMBER(SEARCH("Talenlio",F15))),9, OR(ISNUMBER(SEARCH("Innovation",F15)),F15="Mini Project"),10, OR(ISNUMBER(SEARCH("Data Science",F15)),ISNUMBER(SEARCH("DS",F15))),11, ISNUMBER(SEARCH("Generative AI",F15)),12 =_xlfn.IFS( OR(F15="Selenium (Hands-on)",F15="Guest Lecture: HR Interview"),6, OR(F15="Soft Skill",F15="Soft Skill (Examination)",F15="AWS Training",F15="AWS Session"),7, OR(ISNUMBER(SEARCH("MAD",F15)),ISNUMBER(SEARCH("STQA",F15)),F15="CI/CD Session"),8, OR(ISNUMBER(SEARCH("Cloud",F15)),F15="Industry Readiness Program",ISNUMBER(SEARCH("Talenlio",F15))),9, OR(ISNUMBER(SEARCH("Innovation",F15)),F15="Mini Project"),10, OR(ISNUMBER(SEARCH("Data Science",F15)),ISNUMBER(SEARCH("DS",F15))),11, ISNUMBER(SEARCH("Generative AI",F15)),12 ))))} -> 7 | X15: 1 | Y15: 4 | Z15: Morning
A16: 46191 | B16: Thursday | C16: 3 | D16: 0.5625 | E16: 0.60416667 | F16: CI/CD Session | G16: DB | H16: III | I16: MCA | J16: A | K16: Lab | L16: 103 | M16: =RANDBETWEEN(40,103) -> 80 | N16: =IF(OR(L16="",M16=""),"",M16/L16*100) -> 77.669903 | O16: {=IFERROR(LOOKUP(2, 1/((F$1:F15=F16)*(J$1:J15=J16)*(ROW(F$1:F15)<ROW(F16))), N$1:N15), "")} -> 42.718447 | P16: =IF(C16=1, 0, IF(AND(A16=A15, J16=J15), ROUND(MAX(0, (D16-E15)*24), 2), 0)) -> 2.25 | Q16: Practical | R16: No | S16: =IF(OR(ISNUMBER(SEARCH("Guest", F16)), ISNUMBER(SEARCH("Hands-on", F16)), ISNUMBER(SEARCH("Project", F16)), B16="Friday"), "Yes", "No") -> No | T16: No | U16: =IF(MONTH(A16)=6, IF(DAY(A16)<20, "Sunny", "Cloudy"), IF(OR(MONTH(A16)=7, MONTH(A16)=8), "Rainy", "Sunny")) -> Sunny | V16: No | W16: {=_xlfn.IFS( OR(F16="Selenium (Hands-on)",F16="Guest Lecture: HR Interview"),6, OR(F16="Soft Skill",F16="Soft Skill (Examination)",F16="AWS Training",F16="AWS Session"),7, OR(ISNUMBER(SEARCH("MAD",F16)),ISNUMBER(SEARCH("STQA",F16)),F16="CI/CD Session"),8, OR(ISNUMBER(SEARCH("Cloud",F16)),F16="Industry Readiness Program",ISNUMBER(SEARCH("Talenlio",F16))),9, OR(ISNUMBER(SEARCH("Innovation",F16)),F16="Mini Project"),10, OR(ISNUMBER(SEARCH("Data Science",F16)),ISNUMBER(SEARCH("DS",F16))),11, ISNUMBER(SEARCH("Generative AI",F16)),12 =_xlfn.IFS( OR(F16="Selenium (Hands-on)",F16="Guest Lecture: HR Interview"),6, OR(F16="Soft Skill",F16="Soft Skill (Examination)",F16="AWS Training",F16="AWS Session"),7, OR(ISNUMBER(SEARCH("MAD",F16)),ISNUMBER(SEARCH("STQA",F16)),F16="CI/CD Session"),8, OR(ISNUMBER(SEARCH("Cloud",F16)),F16="Industry Readiness Program",ISNUMBER(SEARCH("Talenlio",F16))),9, OR(ISNUMBER(SEARCH("Innovation",F16)),F16="Mini Project"),10, OR(ISNUMBER(SEARCH("Data Science",F16)),ISNUMBER(SEARCH("DS",F16))),11, ISNUMBER(SEARCH("Generative AI",F16)),12 =_xlfn.IFS( OR(F16="Selenium (Hands-on)",F16="Guest Lecture: HR Interview"),6, OR(F16="Soft Skill",F16="Soft Skill (Examination)",F16="AWS Training",F16="AWS Session"),7, OR(ISNUMBER(SEARCH("MAD",F16)),ISNUMBER(SEARCH("STQA",F16)),F16="CI/CD Session"),8, OR(ISNUMBER(SEARCH("Cloud",F16)),F16="Industry Readiness Program",ISNUMBER(SEARCH("Talenlio",F16))),9, OR(ISNUMBER(SEARCH("Innovation",F16)),F16="Mini Project"),10, OR(ISNUMBER(SEARCH("Data Science",F16)),ISNUMBER(SEARCH("DS",F16))),11, ISNUMBER(SEARCH("Generative AI",F16)),12 =_xlfn.IFS( OR(F16="Selenium (Hands-on)",F16="Guest Lecture: HR Interview"),6, OR(F16="Soft Skill",F16="Soft Skill (Examination)",F16="AWS Training",F16="AWS Session"),7, OR(ISNUMBER(SEARCH("MAD",F16)),ISNUMBER(SEARCH("STQA",F16)),F16="CI/CD Session"),8, OR(ISNUMBER(SEARCH("Cloud",F16)),F16="Industry Readiness Program",ISNUMBER(SEARCH("Talenlio",F16))),9, OR(ISNUMBER(SEARCH("Innovation",F16)),F16="Mini Project"),10, OR(ISNUMBER(SEARCH("Data Science",F16)),ISNUMBER(SEARCH("DS",F16))),11, ISNUMBER(SEARCH("Generative AI",F16)),12 ))))} -> 8 | X16: 1 | Y16: 4 | Z16: Afternoon
A17: 46191 | B17: Thursday | C17: 4 | D17: 0.60416667 | E17: 0.64583333 | F17: CI/CD Session | G17: DB | H17: III | I17: MCA | J17: A | K17: Lab | L17: 103 | M17: =RANDBETWEEN(40,103) -> 69 | N17: =IF(OR(L17="",M17=""),"",M17/L17*100) -> 66.990291 | O17: {=IFERROR(LOOKUP(2, 1/((F$1:F16=F17)*(J$1:J16=J17)*(ROW(F$1:F16)<ROW(F17))), N$1:N16), "")} -> 77.669903 | P17: =IF(C17=1, 0, IF(AND(A17=A16, J17=J16), ROUND(MAX(0, (D17-E16)*24), 2), 0)) -> 0 | Q17: Practical | R17: No | S17: =IF(OR(ISNUMBER(SEARCH("Guest", F17)), ISNUMBER(SEARCH("Hands-on", F17)), ISNUMBER(SEARCH("Project", F17)), B17="Friday"), "Yes", "No") -> No | T17: No | U17: =IF(MONTH(A17)=6, IF(DAY(A17)<20, "Sunny", "Cloudy"), IF(OR(MONTH(A17)=7, MONTH(A17)=8), "Rainy", "Sunny")) -> Sunny | V17: No | W17: {=_xlfn.IFS( OR(F17="Selenium (Hands-on)",F17="Guest Lecture: HR Interview"),6, OR(F17="Soft Skill",F17="Soft Skill (Examination)",F17="AWS Training",F17="AWS Session"),7, OR(ISNUMBER(SEARCH("MAD",F17)),ISNUMBER(SEARCH("STQA",F17)),F17="CI/CD Session"),8, OR(ISNUMBER(SEARCH("Cloud",F17)),F17="Industry Readiness Program",ISNUMBER(SEARCH("Talenlio",F17))),9, OR(ISNUMBER(SEARCH("Innovation",F17)),F17="Mini Project"),10, OR(ISNUMBER(SEARCH("Data Science",F17)),ISNUMBER(SEARCH("DS",F17))),11, ISNUMBER(SEARCH("Generative AI",F17)),12 =_xlfn.IFS( OR(F17="Selenium (Hands-on)",F17="Guest Lecture: HR Interview"),6, OR(F17="Soft Skill",F17="Soft Skill (Examination)",F17="AWS Training",F17="AWS Session"),7, OR(ISNUMBER(SEARCH("MAD",F17)),ISNUMBER(SEARCH("STQA",F17)),F17="CI/CD Session"),8, OR(ISNUMBER(SEARCH("Cloud",F17)),F17="Industry Readiness Program",ISNUMBER(SEARCH("Talenlio",F17))),9, OR(ISNUMBER(SEARCH("Innovation",F17)),F17="Mini Project"),10, OR(ISNUMBER(SEARCH("Data Science",F17)),ISNUMBER(SEARCH("DS",F17))),11, ISNUMBER(SEARCH("Generative AI",F17)),12 =_xlfn.IFS( OR(F17="Selenium (Hands-on)",F17="Guest Lecture: HR Interview"),6, OR(F17="Soft Skill",F17="Soft Skill (Examination)",F17="AWS Training",F17="AWS Session"),7, OR(ISNUMBER(SEARCH("MAD",F17)),ISNUMBER(SEARCH("STQA",F17)),F17="CI/CD Session"),8, OR(ISNUMBER(SEARCH("Cloud",F17)),F17="Industry Readiness Program",ISNUMBER(SEARCH("Talenlio",F17))),9, OR(ISNUMBER(SEARCH("Innovation",F17)),F17="Mini Project"),10, OR(ISNUMBER(SEARCH("Data Science",F17)),ISNUMBER(SEARCH("DS",F17))),11, ISNUMBER(SEARCH("Generative AI",F17)),12 =_xlfn.IFS( OR(F17="Selenium (Hands-on)",F17="Guest Lecture: HR Interview"),6, OR(F17="Soft Skill",F17="Soft Skill (Examination)",F17="AWS Training",F17="AWS Session"),7, OR(ISNUMBER(SEARCH("MAD",F17)),ISNUMBER(SEARCH("STQA",F17)),F17="CI/CD Session"),8, OR(ISNUMBER(SEARCH("Cloud",F17)),F17="Industry Readiness Program",ISNUMBER(SEARCH("Talenlio",F17))),9, OR(ISNUMBER(SEARCH("Innovation",F17)),F17="Mini Project"),10, OR(ISNUMBER(SEARCH("Data Science",F17)),ISNUMBER(SEARCH("DS",F17))),11, ISNUMBER(SEARCH("Generative AI",F17)),12 ))))} -> 8 | X17: 1 | Y17: 4 | Z17: Afternoon
A18: 46192 | B18: Friday | C18: 1 | D18: 0.38541667 | E18: 0.42708333 | F18: Soft Skill | G18: SD | H18: III | I18: MCA | J18: A | K18: Seminar Hall | L18: 103 | M18: =RANDBETWEEN(40,103) -> 97 | N18: =IF(OR(L18="",M18=""),"",M18/L18*100) -> 94.174757 | O18: {=IFERROR(LOOKUP(2, 1/((F$1:F17=F18)*(J$1:J17=J18)*(ROW(F$1:F17)<ROW(F18))), N$1:N17), "")} -> 66.990291 | P18: =IF(C18=1, 0, IF(AND(A18=A17, J18=J17), ROUND(MAX(0, (D18-E17)*24), 2), 0)) -> 0 | Q18: Theory | R18: No | S18: =IF(OR(ISNUMBER(SEARCH("Guest", F18)), ISNUMBER(SEARCH("Hands-on", F18)), ISNUMBER(SEARCH("Project", F18)), B18="Friday"), "Yes", "No") -> Yes | T18: No | U18: =IF(MONTH(A18)=6, IF(DAY(A18)<20, "Sunny", "Cloudy"), IF(OR(MONTH(A18)=7, MONTH(A18)=8), "Rainy", "Sunny")) -> Sunny | V18: No | W18: {=_xlfn.IFS( OR(F18="Selenium (Hands-on)",F18="Guest Lecture: HR Interview"),6, OR(F18="Soft Skill",F18="Soft Skill (Examination)",F18="AWS Training",F18="AWS Session"),7, OR(ISNUMBER(SEARCH("MAD",F18)),ISNUMBER(SEARCH("STQA",F18)),F18="CI/CD Session"),8, OR(ISNUMBER(SEARCH("Cloud",F18)),F18="Industry Readiness Program",ISNUMBER(SEARCH("Talenlio",F18))),9, OR(ISNUMBER(SEARCH("Innovation",F18)),F18="Mini Project"),10, OR(ISNUMBER(SEARCH("Data Science",F18)),ISNUMBER(SEARCH("DS",F18))),11, ISNUMBER(SEARCH("Generative AI",F18)),12 =_xlfn.IFS( OR(F18="Selenium (Hands-on)",F18="Guest Lecture: HR Interview"),6, OR(F18="Soft Skill",F18="Soft Skill (Examination)",F18="AWS Training",F18="AWS Session"),7, OR(ISNUMBER(SEARCH("MAD",F18)),ISNUMBER(SEARCH("STQA",F18)),F18="CI/CD Session"),8, OR(ISNUMBER(SEARCH("Cloud",F18)),F18="Industry Readiness Program",ISNUMBER(SEARCH("Talenlio",F18))),9, OR(ISNUMBER(SEARCH("Innovation",F18)),F18="Mini Project"),10, OR(ISNUMBER(SEARCH("Data Science",F18)),ISNUMBER(SEARCH("DS",F18))),11, ISNUMBER(SEARCH("Generative AI",F18)),12 =_xlfn.IFS( OR(F18="Selenium (Hands-on)",F18="Guest Lecture: HR Interview"),6, OR(F18="Soft Skill",F18="Soft Skill (Examination)",F18="AWS Training",F18="AWS Session"),7, OR(ISNUMBER(SEARCH("MAD",F18)),ISNUMBER(SEARCH("STQA",F18)),F18="CI/CD Session"),8, OR(ISNUMBER(SEARCH("Cloud",F18)),F18="Industry Readiness Program",ISNUMBER(SEARCH("Talenlio",F18))),9, OR(ISNUMBER(SEARCH("Innovation",F18)),F18="Mini Project"),10, OR(ISNUMBER(SEARCH("Data Science",F18)),ISNUMBER(SEARCH("DS",F18))),11, ISNUMBER(SEARCH("Generative AI",F18)),12 =_xlfn.IFS( OR(F18="Selenium (Hands-on)",F18="Guest Lecture: HR Interview"),6, OR(F18="Soft Skill",F18="Soft Skill (Examination)",F18="AWS Training",F18="AWS Session"),7, OR(ISNUMBER(SEARCH("MAD",F18)),ISNUMBER(SEARCH("STQA",F18)),F18="CI/CD Session"),8, OR(ISNUMBER(SEARCH("Cloud",F18)),F18="Industry Readiness Program",ISNUMBER(SEARCH("Talenlio",F18))),9, OR(ISNUMBER(SEARCH("Innovation",F18)),F18="Mini Project"),10, OR(ISNUMBER(SEARCH("Data Science",F18)),ISNUMBER(SEARCH("DS",F18))),11, ISNUMBER(SEARCH("Generative AI",F18)),12 ))))} -> 7 | X18: 1 | Y18: 5 | Z18: Morning
A19: 46192 | B19: Friday | C19: 2 | D19: 0.42708333 | E19: 0.46875 | F19: Soft Skill | G19: SD | H19: III | I19: MCA | J19: A | K19: Seminar Hall | L19: 103 | M19: =RANDBETWEEN(40,103) -> 69 | N19: =IF(OR(L19="",M19=""),"",M19/L19*100) -> 66.990291 | O19: {=IFERROR(LOOKUP(2, 1/((F$1:F18=F19)*(J$1:J18=J19)*(ROW(F$1:F18)<ROW(F19))), N$1:N18), "")} -> 94.174757 | P19: =IF(C19=1, 0, IF(AND(A19=A18, J19=J18), ROUND(MAX(0, (D19-E18)*24), 2), 0)) -> 0 | Q19: Theory | R19: No | S19: =IF(OR(ISNUMBER(SEARCH("Guest", F19)), ISNUMBER(SEARCH("Hands-on", F19)), ISNUMBER(SEARCH("Project", F19)), B19="Friday"), "Yes", "No") -> Yes | T19: No | U19: =IF(MONTH(A19)=6, IF(DAY(A19)<20, "Sunny", "Cloudy"), IF(OR(MONTH(A19)=7, MONTH(A19)=8), "Rainy", "Sunny")) -> Sunny | V19: No | W19: {=_xlfn.IFS( OR(F19="Selenium (Hands-on)",F19="Guest Lecture: HR Interview"),6, OR(F19="Soft Skill",F19="Soft Skill (Examination)",F19="AWS Training",F19="AWS Session"),7, OR(ISNUMBER(SEARCH("MAD",F19)),ISNUMBER(SEARCH("STQA",F19)),F19="CI/CD Session"),8, OR(ISNUMBER(SEARCH("Cloud",F19)),F19="Industry Readiness Program",ISNUMBER(SEARCH("Talenlio",F19))),9, OR(ISNUMBER(SEARCH("Innovation",F19)),F19="Mini Project"),10, OR(ISNUMBER(SEARCH("Data Science",F19)),ISNUMBER(SEARCH("DS",F19))),11, ISNUMBER(SEARCH("Generative AI",F19)),12 =_xlfn.IFS( OR(F19="Selenium (Hands-on)",F19="Guest Lecture: HR Interview"),6, OR(F19="Soft Skill",F19="Soft Skill (Examination)",F19="AWS Training",F19="AWS Session"),7, OR(ISNUMBER(SEARCH("MAD",F19)),ISNUMBER(SEARCH("STQA",F19)),F19="CI/CD Session"),8, OR(ISNUMBER(SEARCH("Cloud",F19)),F19="Industry Readiness Program",ISNUMBER(SEARCH("Talenlio",F19))),9, OR(ISNUMBER(SEARCH("Innovation",F19)),F19="Mini Project"),10, OR(ISNUMBER(SEARCH("Data Science",F19)),ISNUMBER(SEARCH("DS",F19))),11, ISNUMBER(SEARCH("Generative AI",F19)),12 =_xlfn.IFS( OR(F19="Selenium (Hands-on)",F19="Guest Lecture: HR Interview"),6, OR(F19="Soft Skill",F19="Soft Skill (Examination)",F19="AWS Training",F19="AWS Session"),7, OR(ISNUMBER(SEARCH("MAD",F19)),ISNUMBER(SEARCH("STQA",F19)),F19="CI/CD Session"),8, OR(ISNUMBER(SEARCH("Cloud",F19)),F19="Industry Readiness Program",ISNUMBER(SEARCH("Talenlio",F19))),9, OR(ISNUMBER(SEARCH("Innovation",F19)),F19="Mini Project"),10, OR(ISNUMBER(SEARCH("Data Science",F19)),ISNUMBER(SEARCH("DS",F19))),11, ISNUMBER(SEARCH("Generative AI",F19)),12 =_xlfn.IFS( OR(F19="Selenium (Hands-on)",F19="Guest Lecture: HR Interview"),6, OR(F19="Soft Skill",F19="Soft Skill (Examination)",F19="AWS Training",F19="AWS Session"),7, OR(ISNUMBER(SEARCH("MAD",F19)),ISNUMBER(SEARCH("STQA",F19)),F19="CI/CD Session"),8, OR(ISNUMBER(SEARCH("Cloud",F19)),F19="Industry Readiness Program",ISNUMBER(SEARCH("Talenlio",F19))),9, OR(ISNUMBER(SEARCH("Innovation",F19)),F19="Mini Project"),10, OR(ISNUMBER(SEARCH("Data Science",F19)),ISNUMBER(SEARCH("DS",F19))),11, ISNUMBER(SEARCH("Generative AI",F19)),12 ))))} -> 7 | X19: 1 | Y19: 5 | Z19: Morning
A20: 46192 | B20: Friday | C20: 3 | D20: 0.5625 | E20: 0.60416667 | F20: CI/CD Session | G20: DB | H20: III | I20: MCA | J20: A | K20: Lab | L20: 103 | M20: =RANDBETWEEN(40,103) -> 95 | N20: =IF(OR(L20="",M20=""),"",M20/L20*100) -> 92.23301 | O20: {=IFERROR(LOOKUP(2, 1/((F$1:F19=F20)*(J$1:J19=J20)*(ROW(F$1:F19)<ROW(F20))), N$1:N19), "")} -> 66.990291 | P20: =IF(C20=1, 0, IF(AND(A20=A19, J20=J19), ROUND(MAX(0, (D20-E19)*24), 2), 0)) -> 2.25 | Q20: Practical | R20: No | S20: =IF(OR(ISNUMBER(SEARCH("Guest", F20)), ISNUMBER(SEARCH("Hands-on", F20)), ISNUMBER(SEARCH("Project", F20)), B20="Friday"), "Yes", "No") -> Yes | T20: No | U20: =IF(MONTH(A20)=6, IF(DAY(A20)<20, "Sunny", "Cloudy"), IF(OR(MONTH(A20)=7, MONTH(A20)=8), "Rainy", "Sunny")) -> Sunny | V20: No | W20: {=_xlfn.IFS( OR(F20="Selenium (Hands-on)",F20="Guest Lecture: HR Interview"),6, OR(F20="Soft Skill",F20="Soft Skill (Examination)",F20="AWS Training",F20="AWS Session"),7, OR(ISNUMBER(SEARCH("MAD",F20)),ISNUMBER(SEARCH("STQA",F20)),F20="CI/CD Session"),8, OR(ISNUMBER(SEARCH("Cloud",F20)),F20="Industry Readiness Program",ISNUMBER(SEARCH("Talenlio",F20))),9, OR(ISNUMBER(SEARCH("Innovation",F20)),F20="Mini Project"),10, OR(ISNUMBER(SEARCH("Data Science",F20)),ISNUMBER(SEARCH("DS",F20))),11, ISNUMBER(SEARCH("Generative AI",F20)),12 =_xlfn.IFS( OR(F20="Selenium (Hands-on)",F20="Guest Lecture: HR Interview"),6, OR(F20="Soft Skill",F20="Soft Skill (Examination)",F20="AWS Training",F20="AWS Session"),7, OR(ISNUMBER(SEARCH("MAD",F20)),ISNUMBER(SEARCH("STQA",F20)),F20="CI/CD Session"),8, OR(ISNUMBER(SEARCH("Cloud",F20)),F20="Industry Readiness Program",ISNUMBER(SEARCH("Talenlio",F20))),9, OR(ISNUMBER(SEARCH("Innovation",F20)),F20="Mini Project"),10, OR(ISNUMBER(SEARCH("Data Science",F20)),ISNUMBER(SEARCH("DS",F20))),11, ISNUMBER(SEARCH("Generative AI",F20)),12 =_xlfn.IFS( OR(F20="Selenium (Hands-on)",F20="Guest Lecture: HR Interview"),6, OR(F20="Soft Skill",F20="Soft Skill (Examination)",F20="AWS Training",F20="AWS Session"),7, OR(ISNUMBER(SEARCH("MAD",F20)),ISNUMBER(SEARCH("STQA",F20)),F20="CI/CD Session"),8, OR(ISNUMBER(SEARCH("Cloud",F20)),F20="Industry Readiness Program",ISNUMBER(SEARCH("Talenlio",F20))),9, OR(ISNUMBER(SEARCH("Innovation",F20)),F20="Mini Project"),10, OR(ISNUMBER(SEARCH("Data Science",F20)),ISNUMBER(SEARCH("DS",F20))),11, ISNUMBER(SEARCH("Generative AI",F20)),12 =_xlfn.IFS( OR(F20="Selenium (Hands-on)",F20="Guest Lecture: HR Interview"),6, OR(F20="Soft Skill",F20="Soft Skill (Examination)",F20="AWS Training",F20="AWS Session"),7, OR(ISNUMBER(SEARCH("MAD",F20)),ISNUMBER(SEARCH("STQA",F20)),F20="CI/CD Session"),8, OR(ISNUMBER(SEARCH("Cloud",F20)),F20="Industry Readiness Program",ISNUMBER(SEARCH("Talenlio",F20))),9, OR(ISNUMBER(SEARCH("Innovation",F20)),F20="Mini Project"),10, OR(ISNUMBER(SEARCH("Data Science",F20)),ISNUMBER(SEARCH("DS",F20))),11, ISNUMBER(SEARCH("Generative AI",F20)),12 ))))} -> 8 | X20: 1 | Y20: 5 | Z20: Afternoon
A21: 46192 | B21: Friday | C21: 4 | D21: 0.60416667 | E21: 0.64583333 | F21: CI/CD Session | G21: DB | H21: III | I21: MCA | J21: A | K21: Lab | L21: 103 | M21: =RANDBETWEEN(40,103) -> 101 | N21: =IF(OR(L21="",M21=""),"",M21/L21*100) -> 98.058252 | O21: {=IFERROR(LOOKUP(2, 1/((F$1:F20=F21)*(J$1:J20=J21)*(ROW(F$1:F20)<ROW(F21))), N$1:N20), "")} -> 92.23301 | P21: =IF(C21=1, 0, IF(AND(A21=A20, J21=J20), ROUND(MAX(0, (D21-E20)*24), 2), 0)) -> 0 | Q21: Practical | R21: No | S21: =IF(OR(ISNUMBER(SEARCH("Guest", F21)), ISNUMBER(SEARCH("Hands-on", F21)), ISNUMBER(SEARCH("Project", F21)), B21="Friday"), "Yes", "No") -> Yes | T21: No | U21: =IF(MONTH(A21)=6, IF(DAY(A21)<20, "Sunny", "Cloudy"), IF(OR(MONTH(A21)=7, MONTH(A21)=8), "Rainy", "Sunny")) -> Sunny | V21: No | W21: {=_xlfn.IFS( OR(F21="Selenium (Hands-on)",F21="Guest Lecture: HR Interview"),6, OR(F21="Soft Skill",F21="Soft Skill (Examination)",F21="AWS Training",F21="AWS Session"),7, OR(ISNUMBER(SEARCH("MAD",F21)),ISNUMBER(SEARCH("STQA",F21)),F21="CI/CD Session"),8, OR(ISNUMBER(SEARCH("Cloud",F21)),F21="Industry Readiness Program",ISNUMBER(SEARCH("Talenlio",F21))),9, OR(ISNUMBER(SEARCH("Innovation",F21)),F21="Mini Project"),10, OR(ISNUMBER(SEARCH("Data Science",F21)),ISNUMBER(SEARCH("DS",F21))),11, ISNUMBER(SEARCH("Generative AI",F21)),12 =_xlfn.IFS( OR(F21="Selenium (Hands-on)",F21="Guest Lecture: HR Interview"),6, OR(F21="Soft Skill",F21="Soft Skill (Examination)",F21="AWS Training",F21="AWS Session"),7, OR(ISNUMBER(SEARCH("MAD",F21)),ISNUMBER(SEARCH("STQA",F21)),F21="CI/CD Session"),8, OR(ISNUMBER(SEARCH("Cloud",F21)),F21="Industry Readiness Program",ISNUMBER(SEARCH("Talenlio",F21))),9, OR(ISNUMBER(SEARCH("Innovation",F21)),F21="Mini Project"),10, OR(ISNUMBER(SEARCH("Data Science",F21)),ISNUMBER(SEARCH("DS",F21))),11, ISNUMBER(SEARCH("Generative AI",F21)),12 =_xlfn.IFS( OR(F21="Selenium (Hands-on)",F21="Guest Lecture: HR Interview"),6, OR(F21="Soft Skill",F21="Soft Skill (Examination)",F21="AWS Training",F21="AWS Session"),7, OR(ISNUMBER(SEARCH("MAD",F21)),ISNUMBER(SEARCH("STQA",F21)),F21="CI/CD Session"),8, OR(ISNUMBER(SEARCH("Cloud",F21)),F21="Industry Readiness Program",ISNUMBER(SEARCH("Talenlio",F21))),9, OR(ISNUMBER(SEARCH("Innovation",F21)),F21="Mini Project"),10, OR(ISNUMBER(SEARCH("Data Science",F21)),ISNUMBER(SEARCH("DS",F21))),11, ISNUMBER(SEARCH("Generative AI",F21)),12 =_xlfn.IFS( OR(F21="Selenium (Hands-on)",F21="Guest Lecture: HR Interview"),6, OR(F21="Soft Skill",F21="Soft Skill (Examination)",F21="AWS Training",F21="AWS Session"),7, OR(ISNUMBER(SEARCH("MAD",F21)),ISNUMBER(SEARCH("STQA",F21)),F21="CI/CD Session"),8, OR(ISNUMBER(SEARCH("Cloud",F21)),F21="Industry Readiness Program",ISNUMBER(SEARCH("Talenlio",F21))),9, OR(ISNUMBER(SEARCH("Innovation",F21)),F21="Mini Project"),10, OR(ISNUMBER(SEARCH("Data Science",F21)),ISNUMBER(SEARCH("DS",F21))),11, ISNUMBER(SEARCH("Generative AI",F21)),12 ))))} -> 8 | X21: 1 | Y21: 5 | Z21: Afternoon
